2018-11-07 17:30:29,342 ERROR: Exception on /submit [POST] [in /Users/duarteocarmo/anaconda/envs/dev.to/lib/python3.7/site-packages/flask/app.py:1761]
Traceback (most recent call last):
  File "/Users/duarteocarmo/anaconda/envs/dev.to/lib/python3.7/site-packages/flask/app.py", line 2292, in wsgi_app
    response = self.full_dispatch_request()
  File "/Users/duarteocarmo/anaconda/envs/dev.to/lib/python3.7/site-packages/flask/app.py", line 1815, in full_dispatch_request
    rv = self.handle_user_exception(e)
  File "/Users/duarteocarmo/anaconda/envs/dev.to/lib/python3.7/site-packages/flask/app.py", line 1718, in handle_user_exception
    reraise(exc_type, exc_value, tb)
  File "/Users/duarteocarmo/anaconda/envs/dev.to/lib/python3.7/site-packages/flask/_compat.py", line 35, in reraise
    raise value
  File "/Users/duarteocarmo/anaconda/envs/dev.to/lib/python3.7/site-packages/flask/app.py", line 1813, in full_dispatch_request
    rv = self.dispatch_request()
  File "/Users/duarteocarmo/anaconda/envs/dev.to/lib/python3.7/site-packages/flask/app.py", line 1799, in dispatch_request
    return self.view_functions[rule.endpoint](**req.view_args)
  File "/Users/duarteocarmo/anaconda/envs/dev.to/lib/python3.7/site-packages/flask_login/utils.py", line 261, in decorated_view
    return func(*args, **kwargs)
  File "/Users/duarteocarmo/SourceTree_Repos/dev.pt/app/routes.py", line 85, in submit
    author=current_user.username)
  File "<string>", line 4, in __init__
  File "/Users/duarteocarmo/anaconda/envs/dev.to/lib/python3.7/site-packages/sqlalchemy/orm/state.py", line 424, in _initialize_instance
    manager.dispatch.init_failure(self, args, kwargs)
  File "/Users/duarteocarmo/anaconda/envs/dev.to/lib/python3.7/site-packages/sqlalchemy/util/langhelpers.py", line 66, in __exit__
    compat.reraise(exc_type, exc_value, exc_tb)
  File "/Users/duarteocarmo/anaconda/envs/dev.to/lib/python3.7/site-packages/sqlalchemy/util/compat.py", line 249, in reraise
    raise value
  File "/Users/duarteocarmo/anaconda/envs/dev.to/lib/python3.7/site-packages/sqlalchemy/orm/state.py", line 421, in _initialize_instance
    return manager.original_init(*mixed[1:], **kwargs)
  File "/Users/duarteocarmo/anaconda/envs/dev.to/lib/python3.7/site-packages/sqlalchemy/ext/declarative/base.py", line 748, in _declarative_constructor
    setattr(self, k, kwargs[k])
  File "/Users/duarteocarmo/anaconda/envs/dev.to/lib/python3.7/site-packages/sqlalchemy/orm/attributes.py", line 229, in __set__
    instance_dict(instance), value, None)
  File "/Users/duarteocarmo/anaconda/envs/dev.to/lib/python3.7/site-packages/sqlalchemy/orm/attributes.py", line 815, in set
    value = self.fire_replace_event(state, dict_, value, old, initiator)
  File "/Users/duarteocarmo/anaconda/envs/dev.to/lib/python3.7/site-packages/sqlalchemy/orm/attributes.py", line 835, in fire_replace_event
    state, value, previous, initiator or self._replace_token)
  File "/Users/duarteocarmo/anaconda/envs/dev.to/lib/python3.7/site-packages/sqlalchemy/orm/attributes.py", line 1183, in emit_backref_from_scalar_set_event
    child_state, child_dict = instance_state(child),\
AttributeError: 'str' object has no attribute '_sa_instance_state'
2018-11-07 17:32:48,845 INFO: Devpt startup [in /Users/duarteocarmo/SourceTree_Repos/dev.pt/app/__init__.py:28]
2018-11-07 17:33:00,920 ERROR: Exception on /submit [POST] [in /Users/duarteocarmo/anaconda/envs/dev.to/lib/python3.7/site-packages/flask/app.py:1761]
Traceback (most recent call last):
  File "/Users/duarteocarmo/anaconda/envs/dev.to/lib/python3.7/site-packages/flask/app.py", line 2292, in wsgi_app
    response = self.full_dispatch_request()
  File "/Users/duarteocarmo/anaconda/envs/dev.to/lib/python3.7/site-packages/flask/app.py", line 1815, in full_dispatch_request
    rv = self.handle_user_exception(e)
  File "/Users/duarteocarmo/anaconda/envs/dev.to/lib/python3.7/site-packages/flask/app.py", line 1718, in handle_user_exception
    reraise(exc_type, exc_value, tb)
  File "/Users/duarteocarmo/anaconda/envs/dev.to/lib/python3.7/site-packages/flask/_compat.py", line 35, in reraise
    raise value
  File "/Users/duarteocarmo/anaconda/envs/dev.to/lib/python3.7/site-packages/flask/app.py", line 1813, in full_dispatch_request
    rv = self.dispatch_request()
  File "/Users/duarteocarmo/anaconda/envs/dev.to/lib/python3.7/site-packages/flask/app.py", line 1799, in dispatch_request
    return self.view_functions[rule.endpoint](**req.view_args)
  File "/Users/duarteocarmo/anaconda/envs/dev.to/lib/python3.7/site-packages/flask_login/utils.py", line 261, in decorated_view
    return func(*args, **kwargs)
  File "/Users/duarteocarmo/SourceTree_Repos/dev.pt/app/routes.py", line 85, in submit
    author=current_user.username)
  File "<string>", line 4, in __init__
  File "/Users/duarteocarmo/anaconda/envs/dev.to/lib/python3.7/site-packages/sqlalchemy/orm/state.py", line 424, in _initialize_instance
    manager.dispatch.init_failure(self, args, kwargs)
  File "/Users/duarteocarmo/anaconda/envs/dev.to/lib/python3.7/site-packages/sqlalchemy/util/langhelpers.py", line 66, in __exit__
    compat.reraise(exc_type, exc_value, exc_tb)
  File "/Users/duarteocarmo/anaconda/envs/dev.to/lib/python3.7/site-packages/sqlalchemy/util/compat.py", line 249, in reraise
    raise value
  File "/Users/duarteocarmo/anaconda/envs/dev.to/lib/python3.7/site-packages/sqlalchemy/orm/state.py", line 421, in _initialize_instance
    return manager.original_init(*mixed[1:], **kwargs)
  File "/Users/duarteocarmo/anaconda/envs/dev.to/lib/python3.7/site-packages/sqlalchemy/ext/declarative/base.py", line 748, in _declarative_constructor
    setattr(self, k, kwargs[k])
  File "/Users/duarteocarmo/anaconda/envs/dev.to/lib/python3.7/site-packages/sqlalchemy/orm/attributes.py", line 229, in __set__
    instance_dict(instance), value, None)
  File "/Users/duarteocarmo/anaconda/envs/dev.to/lib/python3.7/site-packages/sqlalchemy/orm/attributes.py", line 815, in set
    value = self.fire_replace_event(state, dict_, value, old, initiator)
  File "/Users/duarteocarmo/anaconda/envs/dev.to/lib/python3.7/site-packages/sqlalchemy/orm/attributes.py", line 835, in fire_replace_event
    state, value, previous, initiator or self._replace_token)
  File "/Users/duarteocarmo/anaconda/envs/dev.to/lib/python3.7/site-packages/sqlalchemy/orm/attributes.py", line 1183, in emit_backref_from_scalar_set_event
    child_state, child_dict = instance_state(child),\
AttributeError: 'str' object has no attribute '_sa_instance_state'
2018-11-07 17:34:10,595 INFO: Devpt startup [in /Users/duarteocarmo/SourceTree_Repos/dev.pt/app/__init__.py:28]
2018-11-07 17:38:59,287 INFO: Devpt startup [in /Users/duarteocarmo/SourceTree_Repos/dev.pt/app/__init__.py:28]
2018-11-07 17:43:38,406 INFO: Devpt startup [in /Users/duarteocarmo/SourceTree_Repos/dev.pt/app/__init__.py:28]
2018-11-07 17:44:11,591 INFO: Devpt startup [in /Users/duarteocarmo/SourceTree_Repos/dev.pt/app/__init__.py:28]
2018-11-07 17:46:20,529 INFO: Devpt startup [in /Users/duarteocarmo/SourceTree_Repos/dev.pt/app/__init__.py:28]
