2018-11-07 17:46:39,236 ERROR: Exception on /submit [POST] [in /Users/duarteocarmo/anaconda/envs/dev.to/lib/python3.7/site-packages/flask/app.py:1761]
Traceback (most recent call last):
  File "/Users/duarteocarmo/anaconda/envs/dev.to/lib/python3.7/site-packages/flask/app.py", line 2292, in wsgi_app
    response = self.full_dispatch_request()
  File "/Users/duarteocarmo/anaconda/envs/dev.to/lib/python3.7/site-packages/flask/app.py", line 1815, in full_dispatch_request
    rv = self.handle_user_exception(e)
  File "/Users/duarteocarmo/anaconda/envs/dev.to/lib/python3.7/site-packages/flask/app.py", line 1718, in handle_user_exception
    reraise(exc_type, exc_value, tb)
  File "/Users/duarteocarmo/anaconda/envs/dev.to/lib/python3.7/site-packages/flask/_compat.py", line 35, in reraise
    raise value
  File "/Users/duarteocarmo/anaconda/envs/dev.to/lib/python3.7/site-packages/flask/app.py", line 1813, in full_dispatch_request
    rv = self.dispatch_request()
  File "/Users/duarteocarmo/anaconda/envs/dev.to/lib/python3.7/site-packages/flask/app.py", line 1799, in dispatch_request
    return self.view_functions[rule.endpoint](**req.view_args)
  File "/Users/duarteocarmo/anaconda/envs/dev.to/lib/python3.7/site-packages/flask_login/utils.py", line 261, in decorated_view
    return func(*args, **kwargs)
  File "/Users/duarteocarmo/SourceTree_Repos/dev.pt/app/routes.py", line 87, in submit
    author=current_user.username,
  File "<string>", line 4, in __init__
  File "/Users/duarteocarmo/anaconda/envs/dev.to/lib/python3.7/site-packages/sqlalchemy/orm/state.py", line 424, in _initialize_instance
    manager.dispatch.init_failure(self, args, kwargs)
  File "/Users/duarteocarmo/anaconda/envs/dev.to/lib/python3.7/site-packages/sqlalchemy/util/langhelpers.py", line 66, in __exit__
    compat.reraise(exc_type, exc_value, exc_tb)
  File "/Users/duarteocarmo/anaconda/envs/dev.to/lib/python3.7/site-packages/sqlalchemy/util/compat.py", line 249, in reraise
    raise value
  File "/Users/duarteocarmo/anaconda/envs/dev.to/lib/python3.7/site-packages/sqlalchemy/orm/state.py", line 421, in _initialize_instance
    return manager.original_init(*mixed[1:], **kwargs)
  File "/Users/duarteocarmo/anaconda/envs/dev.to/lib/python3.7/site-packages/sqlalchemy/ext/declarative/base.py", line 748, in _declarative_constructor
    setattr(self, k, kwargs[k])
  File "/Users/duarteocarmo/anaconda/envs/dev.to/lib/python3.7/site-packages/sqlalchemy/orm/attributes.py", line 229, in __set__
    instance_dict(instance), value, None)
  File "/Users/duarteocarmo/anaconda/envs/dev.to/lib/python3.7/site-packages/sqlalchemy/orm/attributes.py", line 815, in set
    value = self.fire_replace_event(state, dict_, value, old, initiator)
  File "/Users/duarteocarmo/anaconda/envs/dev.to/lib/python3.7/site-packages/sqlalchemy/orm/attributes.py", line 835, in fire_replace_event
    state, value, previous, initiator or self._replace_token)
  File "/Users/duarteocarmo/anaconda/envs/dev.to/lib/python3.7/site-packages/sqlalchemy/orm/attributes.py", line 1183, in emit_backref_from_scalar_set_event
    child_state, child_dict = instance_state(child),\
AttributeError: 'str' object has no attribute '_sa_instance_state'
2018-11-07 17:48:53,710 INFO: Devpt startup [in /Users/duarteocarmo/SourceTree_Repos/dev.pt/app/__init__.py:28]
2018-11-07 17:50:18,438 INFO: Devpt startup [in /Users/duarteocarmo/SourceTree_Repos/dev.pt/app/__init__.py:28]
2018-11-07 17:51:16,595 INFO: Devpt startup [in /Users/duarteocarmo/SourceTree_Repos/dev.pt/app/__init__.py:28]
2018-11-07 17:52:28,335 INFO: Devpt startup [in /Users/duarteocarmo/SourceTree_Repos/dev.pt/app/__init__.py:28]
2018-11-07 17:53:06,270 INFO: Devpt startup [in /Users/duarteocarmo/SourceTree_Repos/dev.pt/app/__init__.py:28]
2018-11-07 17:53:20,730 INFO: Devpt startup [in /Users/duarteocarmo/SourceTree_Repos/dev.pt/app/__init__.py:28]
2018-11-07 18:00:39,630 INFO: Devpt startup [in /Users/duarteocarmo/SourceTree_Repos/dev.pt/app/__init__.py:28]
2018-11-07 18:01:29,476 INFO: Devpt startup [in /Users/duarteocarmo/SourceTree_Repos/dev.pt/app/__init__.py:28]
2018-11-07 18:02:52,253 INFO: Devpt startup [in /Users/duarteocarmo/SourceTree_Repos/dev.pt/app/__init__.py:28]
2018-11-07 18:09:22,478 INFO: Devpt startup [in /Users/duarteocarmo/SourceTree_Repos/dev.pt/app/__init__.py:28]
2018-11-07 18:09:34,444 INFO: Devpt startup [in /Users/duarteocarmo/SourceTree_Repos/dev.pt/app/__init__.py:28]
2018-11-07 18:16:02,667 INFO: Devpt startup [in /Users/duarteocarmo/SourceTree_Repos/dev.pt/app/__init__.py:28]
2018-11-08 16:20:34,311 INFO: Devpt startup [in /Users/duarteocarmo/SourceTree_Repos/dev.pt/app/__init__.py:28]
2018-11-08 16:34:44,963 INFO: Devpt startup [in /Users/duarteocarmo/SourceTree_Repos/dev.pt/app/__init__.py:28]
2018-11-08 16:34:49,184 INFO: Devpt startup [in /Users/duarteocarmo/SourceTree_Repos/dev.pt/app/__init__.py:28]
2018-11-08 16:42:51,055 INFO: Devpt startup [in /Users/duarteocarmo/SourceTree_Repos/dev.pt/app/__init__.py:28]
2018-11-08 16:42:57,951 INFO: Devpt startup [in /Users/duarteocarmo/SourceTree_Repos/dev.pt/app/__init__.py:28]
2018-11-08 16:43:28,801 INFO: Devpt startup [in /Users/duarteocarmo/SourceTree_Repos/dev.pt/app/__init__.py:28]
2018-11-08 16:43:44,089 INFO: Devpt startup [in /Users/duarteocarmo/SourceTree_Repos/dev.pt/app/__init__.py:28]
2018-11-08 16:44:37,599 INFO: Devpt startup [in /Users/duarteocarmo/SourceTree_Repos/dev.pt/app/__init__.py:28]
2018-11-08 16:45:19,737 INFO: Devpt startup [in /Users/duarteocarmo/SourceTree_Repos/dev.pt/app/__init__.py:28]
2018-11-08 16:45:32,577 INFO: Devpt startup [in /Users/duarteocarmo/SourceTree_Repos/dev.pt/app/__init__.py:28]
2018-11-08 16:45:42,013 INFO: Devpt startup [in /Users/duarteocarmo/SourceTree_Repos/dev.pt/app/__init__.py:28]
2018-11-08 16:53:42,414 INFO: Devpt startup [in /Users/duarteocarmo/SourceTree_Repos/dev.pt/app/__init__.py:28]
2018-11-08 16:54:21,633 INFO: Devpt startup [in /Users/duarteocarmo/SourceTree_Repos/dev.pt/app/__init__.py:28]
2018-11-08 16:55:09,560 INFO: Devpt startup [in /Users/duarteocarmo/SourceTree_Repos/dev.pt/app/__init__.py:28]
2018-11-08 16:55:34,828 INFO: Devpt startup [in /Users/duarteocarmo/SourceTree_Repos/dev.pt/app/__init__.py:28]
2018-11-08 16:55:54,628 INFO: Devpt startup [in /Users/duarteocarmo/SourceTree_Repos/dev.pt/app/__init__.py:28]
2018-11-08 16:56:54,427 INFO: Devpt startup [in /Users/duarteocarmo/SourceTree_Repos/dev.pt/app/__init__.py:28]
2018-11-08 16:58:00,794 INFO: Devpt startup [in /Users/duarteocarmo/SourceTree_Repos/dev.pt/app/__init__.py:28]
2018-11-08 17:01:40,931 INFO: Devpt startup [in /Users/duarteocarmo/SourceTree_Repos/dev.pt/app/__init__.py:28]
2018-11-08 17:01:44,166 ERROR: Exception on /upvote/3 [GET] [in /Users/duarteocarmo/anaconda/envs/dev.to/lib/python3.7/site-packages/flask/app.py:1761]
Traceback (most recent call last):
  File "/Users/duarteocarmo/anaconda/envs/dev.to/lib/python3.7/site-packages/flask/app.py", line 2292, in wsgi_app
    response = self.full_dispatch_request()
  File "/Users/duarteocarmo/anaconda/envs/dev.to/lib/python3.7/site-packages/flask/app.py", line 1815, in full_dispatch_request
    rv = self.handle_user_exception(e)
  File "/Users/duarteocarmo/anaconda/envs/dev.to/lib/python3.7/site-packages/flask/app.py", line 1718, in handle_user_exception
    reraise(exc_type, exc_value, tb)
  File "/Users/duarteocarmo/anaconda/envs/dev.to/lib/python3.7/site-packages/flask/_compat.py", line 35, in reraise
    raise value
  File "/Users/duarteocarmo/anaconda/envs/dev.to/lib/python3.7/site-packages/flask/app.py", line 1813, in full_dispatch_request
    rv = self.dispatch_request()
  File "/Users/duarteocarmo/anaconda/envs/dev.to/lib/python3.7/site-packages/flask/app.py", line 1799, in dispatch_request
    return self.view_functions[rule.endpoint](**req.view_args)
  File "/Users/duarteocarmo/anaconda/envs/dev.to/lib/python3.7/site-packages/flask_login/utils.py", line 261, in decorated_view
    return func(*args, **kwargs)
  File "/Users/duarteocarmo/SourceTree_Repos/dev.pt/app/routes.py", line 105, in upvote
    if voted is False:
UnboundLocalError: local variable 'voted' referenced before assignment
2018-11-08 17:03:36,237 ERROR: Exception on /upvote/4 [GET] [in /Users/duarteocarmo/anaconda/envs/dev.to/lib/python3.7/site-packages/flask/app.py:1761]
Traceback (most recent call last):
  File "/Users/duarteocarmo/anaconda/envs/dev.to/lib/python3.7/site-packages/flask/app.py", line 2292, in wsgi_app
    response = self.full_dispatch_request()
  File "/Users/duarteocarmo/anaconda/envs/dev.to/lib/python3.7/site-packages/flask/app.py", line 1815, in full_dispatch_request
    rv = self.handle_user_exception(e)
  File "/Users/duarteocarmo/anaconda/envs/dev.to/lib/python3.7/site-packages/flask/app.py", line 1718, in handle_user_exception
    reraise(exc_type, exc_value, tb)
  File "/Users/duarteocarmo/anaconda/envs/dev.to/lib/python3.7/site-packages/flask/_compat.py", line 35, in reraise
    raise value
  File "/Users/duarteocarmo/anaconda/envs/dev.to/lib/python3.7/site-packages/flask/app.py", line 1813, in full_dispatch_request
    rv = self.dispatch_request()
  File "/Users/duarteocarmo/anaconda/envs/dev.to/lib/python3.7/site-packages/flask/app.py", line 1799, in dispatch_request
    return self.view_functions[rule.endpoint](**req.view_args)
  File "/Users/duarteocarmo/anaconda/envs/dev.to/lib/python3.7/site-packages/flask_login/utils.py", line 261, in decorated_view
    return func(*args, **kwargs)
  File "/Users/duarteocarmo/SourceTree_Repos/dev.pt/app/routes.py", line 105, in upvote
    if voted is False:
UnboundLocalError: local variable 'voted' referenced before assignment
